Workbook

Sheet expanded_supply_chain_data
A1: Product type | B1: SKU | C1: Price | D1: Availability | E1: Number of products sold | F1: Revenue generated | G1: Customer demographics | H1: Stock levels | I1: Lead times | J1: Order quantities | K1: Shipping times | L1: Shipping carriers | M1: Shipping costs | N1: Supplier name | O1: Location | P1: Latitude | Q1: Longitude | R1: Lead time | S1: Production volumes | T1: Manufacturing lead time | U1: Manufacturing costs | V1: Inspection results | W1: Defect rates | X1: Transportation modes | Y1: Routes | Z1: Costs
A2: Cosmetics | B2: SKU0 | C2: 27.263729 | D2: 89 | E2: 732 | F2: 17961.345 | G2: Non-binary | H2: 51 | I2: 1 | J2: 67 | K2: 6 | L2: Carrier A | M2: 3.1846804 | N2: Supplier 5 | O2: Houston | P2: =VLOOKUP(O2, Coordinates!$A$2:$C$6, 2, FALSE) -> 29.7604 | Q2: =VLOOKUP(O2, Coordinates!$A$2:$C$6, 3, FALSE) -> -95.3698 | R2: 17 | S2: 219 | T2: 19 | U2: 88.894451 | V2: Pass | W2: 4.2303384 | X2: Sea | Y2: Route A | Z2: 447.33292
A3: skincare | B3: SKU1 | C3: 88.229993 | D3: 56 | E3: 180 | F3: 9665.0633 | G3: Male | H3: 33 | I3: 13 | J3: 22 | K3: 4 | L3: Carrier C | M3: 4.560686 | N3: Supplier 3 | O3: Miami | P3: =VLOOKUP(O3, Coordinates!$A$2:$C$6, 2, FALSE) -> 25.7617 | Q3: =VLOOKUP(O3, Coordinates!$A$2:$C$6, 3, FALSE) -> -80.1918 | R3: 9 | S3: 641 | T3: 7 | U3: 77.537855 | V3: Fail | W3: 0.87655007 | X3: Rail | Y3: Route C | Z3: 575.38546
A4: Skincare | B4: SKU2 | C4: 31.386499 | D4: 94 | E4: 874 | F4: 2139.9029 | G4: Male | H4: 66 | I4: 27 | J4: 82 | K4: 8 | L4: Carrier B | M4: 13.486415 | N4: Supplier 4 | O4: Miami | P4: =VLOOKUP(O4, Coordinates!$A$2:$C$6, 2, FALSE) -> 25.7617 | Q4: =VLOOKUP(O4, Coordinates!$A$2:$C$6, 3, FALSE) -> -80.1918 | R4: 28 | S4: 659 | T4: 26 | U4: 63.234417 | V4: Fail | W4: 3.7227451 | X4: Road | Y4: Route C | Z4: 884.80039
A5: Cosmetics | B5: SKU3 | C5: 24.532826 | D5: 93 | E5: 257 | F5: 5674.4426 | G5: Unknown | H5: 38 | I5: 18 | J5: 15 | K5: 5 | L5: Carrier A | M5: 14.559359 | N5: Supplier 4 | O5: Miami | P5: =VLOOKUP(O5, Coordinates!$A$2:$C$6, 2, FALSE) -> 25.7617 | Q5: =VLOOKUP(O5, Coordinates!$A$2:$C$6, 3, FALSE) -> -80.1918 | R5: 29 | S5: 278 | T5: 14 | U5: 86.900333 | V5: Fail | W5: 3.7581735 | X5: Road | Y5: Route A | Z5: 806.85593
A6: HAIRCARE | B6: SKU4 | C6: 5.0315881 | D6: 84 | E6: 970 | F6: 5328.4745 | G6: Unknown | H6: 7 | I6: 18 | J6: 96 | K6: 5 | L6: Carrier C | M6: 14.279826 | N6: Supplier 1 | O6: Houston | P6: =VLOOKUP(O6, Coordinates!$A$2:$C$6, 2, FALSE) -> 29.7604 | Q6: =VLOOKUP(O6, Coordinates!$A$2:$C$6, 3, FALSE) -> -95.3698 | R6: 9 | S6: 193 | T6: 21 | U6: 33.47042 | V6: Pass | W6: 3.6129092 | X6: Air | Y6: Route A | Z6: 994.77193
A7: Skincare | B7: SKU5 | C7: 6.6803419 | D7: 85 | E7: 250 | F7: 4386.8064 | G7: Female | H7: 95 | I7: 13 | J7: 67 | K7: 9 | L7: Carrier B | M7: 3.7069796 | N7: Supplier 4 | O7: Miami | P7: =VLOOKUP(O7, Coordinates!$A$2:$C$6, 2, FALSE) -> 25.7617 | Q7: =VLOOKUP(O7, Coordinates!$A$2:$C$6, 3, FALSE) -> -80.1918 | R7: 27 | S7: 666 | T7: 14 | U7: 91.848361 | V7: Pending | W7: 4.0351145 | X7: Road | Y7: Route A | Z7: 762.11738
A8: Skincare | B8: SKU6 | C8: 62.242551 | D8: 61 | E8: 743 | F8: 4268.7021 | G8: Male | H8: 28 | I8: 22 | J8: 26 | K8: 8 | L8: Carrier A | M8: 13.612519 | N8: Supplier 2 | O8: Los Angeles | P8: =VLOOKUP(O8, Coordinates!$A$2:$C$6, 2, FALSE) -> 34.0522 | Q8: =VLOOKUP(O8, Coordinates!$A$2:$C$6, 3, FALSE) -> -118.2437 | R8: 28 | S8: 847 | T8: 18 | U8: 43.280915 | V8: Pass | W8: 3.3410593 | X8: Air | Y8: Route A | Z8: 293.07721
A9: Cosmetics | B9: SKU7 | C9: 20.637155 | D9: 22 | E9: 110 | F9: 2043.0784 | G9: Unknown | H9: 21 | I9: 30 | J9: 82 | K9: 8 | L9: Carrier A | M9: 2.9810742 | N9: Supplier 2 | O9: Los Angeles | P9: =VLOOKUP(O9, Coordinates!$A$2:$C$6, 2, FALSE) -> 34.0522 | Q9: =VLOOKUP(O9, Coordinates!$A$2:$C$6, 3, FALSE) -> -118.2437 | R9: 11 | S9: 401 | T9: 10 | U9: 85.280683 | V9: Pass | W9: 1.3946187 | X9: Rail | Y9: Route B | Z9: 726.47214
A10: Haircare | B10: SKU8 | C10: 41.71378 | D10: 35 | E10: 197 | F10: 7169.8476 | G10: Male | H10: 83 | I10: 14 | J10: 21 | K10: 5 | L10: Carrier A | M10: 8.1072429 | N10: Supplier 2 | O10: Miami | P10: =VLOOKUP(O10, Coordinates!$A$2:$C$6, 2, FALSE) -> 25.7617 | Q10: =VLOOKUP(O10, Coordinates!$A$2:$C$6, 3, FALSE) -> -80.1918 | R10: 17 | S10: 898 | T10: 3 | U10: 12.849905 | V10: Pass | W10: 1.3030851 | X10: Sea | Y10: Route B | Z10: 654.18759
A11: HAIRCARE | B11: SKU9 | C11: 58.621904 | D11: 16 | E11: 320 | F11: 4925.9298 | G11: Female | H11: 69 | I11: 11 | J11: 95 | K11: 8 | L11: Carrier A | M11: 10.011287 | N11: Supplier 3 | O11: Miami | P11: =VLOOKUP(O11, Coordinates!$A$2:$C$6, 2, FALSE) -> 25.7617 | Q11: =VLOOKUP(O11, Coordinates!$A$2:$C$6, 3, FALSE) -> -80.1918 | R11: 14 | S11: 517 | T11: 6 | U11: 30.895229 | V11: Pending | W11: 1.6225897 | X11: Sea | Y11: Route A | Z11: 289.1079
A12: Cosmetics | B12: SKU10 | C12: 26.518744 | D12: 50 | E12: 306 | F12: 7303.2622 | G12: Male | H12: 60 | I12: 7 | J12: 61 | K12: 10 | L12: Carrier C | M12: 7.4745362 | N12: Supplier 2 | O12: Chicago | P12: =VLOOKUP(O12, Coordinates!$A$2:$C$6, 2, FALSE) -> 41.8781 | Q12: =VLOOKUP(O12, Coordinates!$A$2:$C$6, 3, FALSE) -> -87.6298 | R12: 18 | S12: 959 | T12: 29 | U12: 83.564232 | V12: Pending | W12: 2.6019818 | X12: Rail | Y12: Route C | Z12: 316.86565
A13: HAIRCARE | B13: SKU11 | C13: 25.116758 | D13: 43 | E13: 552 | F13: 8344.3015 | G13: Female | H13: 42 | I13: 18 | J13: 85 | K13: 7 | L13: Carrier A | M13: 14.325724 | N13: Supplier 2 | O13: New York | P13: =VLOOKUP(O13, Coordinates!$A$2:$C$6, 2, FALSE) -> 40.7128 | Q13: =VLOOKUP(O13, Coordinates!$A$2:$C$6, 3, FALSE) -> -74.006 | R13: 18 | S13: 685 | T13: 22 | U13: 70.441666 | V13: Pass | W13: 4.0222696 | X13: Air | Y13: Route B | Z13: 687.50813
A14: HAIRCARE | B14: SKU12 | C14: 51.037151 | D14: 17 | E14: 958 | F14: 8223.0467 | G14: Female | H14: 48 | I14: 21 | J14: 79 | K14: 1 | L14: Carrier A | M14: 5.6649781 | N14: Supplier 5 | O14: Los Angeles | P14: =VLOOKUP(O14, Coordinates!$A$2:$C$6, 2, FALSE) -> 34.0522 | Q14: =VLOOKUP(O14, Coordinates!$A$2:$C$6, 3, FALSE) -> -118.2437 | R14: 12 | S14: 551 | T14: 23 | U14: 38.739773 | V14: Fail | W14: 2.4932188 | X14: Air | Y14: Route A | Z14: 827.03679
A15: Skincare | B15: SKU13 | C15: 76.654087 | D15: 80 | E15: 720 | F15: 5377.5247 | H15: 28 | I15: 22 | J15: 82 | K15: 7 | L15: Carrier A | M15: 8.3832873 | N15: Supplier 3 | O15: Houston | P15: =VLOOKUP(O15, Coordinates!$A$2:$C$6, 2, FALSE) -> 29.7604 | Q15: =VLOOKUP(O15, Coordinates!$A$2:$C$6, 3, FALSE) -> -95.3698 | R15: 18 | S15: 516 | T15: 22 | U15: 13.722742 | V15: Pass | W15: 1.4902135 | X15: Rail | Y15: Route C | Z15: 786.16366
A16: skincare | B16: SKU14 | C16: 63.852286 | D16: 58 | E16: 938 | F16: 3686.056 | G16: Unknown | H16: 80 | I16: 4 | J16: 61 | K16: 8 | L16: Carrier A | M16: 2.0562991 | N16: Supplier 2 | O16: Houston | P16: =VLOOKUP(O16, Coordinates!$A$2:$C$6, 2, FALSE) -> 29.7604 | Q16: =VLOOKUP(O16, Coordinates!$A$2:$C$6, 3, FALSE) -> -95.3698 | R16: 8 | S16: 923 | T16: 9 | U16: 25.648076 | V16: Fail | W16: 4.4198715 | X16: Road | Y16: Route B | Z16: 645.7707
A17: HAIRCARE | B17: SKU15 | C17: 33.24873 | D17: 2 | E17: 783 | F17: 6742.8345 | G17: Non-binary | H17: 30 | I17: 17 | J17: 46 | K17: 3 | L17: Carrier A | M17: 12.931144 | N17: Supplier 1 | O17: Miami | P17: =VLOOKUP(O17, Coordinates!$A$2:$C$6, 2, FALSE) -> 25.7617 | Q17: =VLOOKUP(O17, Coordinates!$A$2:$C$6, 3, FALSE) -> -80.1918 | R17: 29 | S17: 221 | T17: 14 | U17: 33.324882 | V17: Pass | W17: 0.27544979 | X17: Road | Y17: Route B | Z17: 943.78806
A18: cosmetics | B18: SKU16 | C18: 35.793564 | D18: 4 | E18: 272 | F18: 8762.2645 | G18: Non-binary | H18: 52 | I18: 19 | J18: 12 | K18: 9 | L18: Carrier B | M18: 6.7870875 | N18: Supplier 2 | O18: New York | P18: =VLOOKUP(O18, Coordinates!$A$2:$C$6, 2, FALSE) -> 40.7128 | Q18: =VLOOKUP(O18, Coordinates!$A$2:$C$6, 3, FALSE) -> -74.006 | R18: 8 | S18: 156 | T18: 21 | U18: 90.050286 | V18: Pass | W18: 3.9854574 | X18: Road | Y18: Route A | Z18: 757.94098
A19: Skincare | B19: SKU17 | C19: 21.213152 | D19: 85 | E19: 174 | F19: 3124.0714 | G19: Unknown | H19: 33 | I19: 14 | J19: 17 | K19: 8 | L19: Carrier C | M19: 10.80745 | N19: Supplier 3 | O19: Los Angeles | P19: =VLOOKUP(O19, Coordinates!$A$2:$C$6, 2, FALSE) -> 34.0522 | Q19: =VLOOKUP(O19, Coordinates!$A$2:$C$6, 3, FALSE) -> -118.2437 | R19: 26 | S19: 884 | T19: 21 | U19: 28.33521 | V19: Pending | W19: 3.9219088 | X19: Rail | Y19: Route C | Z19: 587.72436
A20: Haircare | B20: SKU18 | C20: 12.089832 | D20: 39 | E20: 555 | F20: 7574.6319 | G20: Male | H20: 37 | I20: 10 | J20: 19 | K20: 2 | L20: Carrier B | M20: 10.551439 | N20: Supplier 4 | O20: Miami | P20: =VLOOKUP(O20, Coordinates!$A$2:$C$6, 2, FALSE) -> 25.7617 | Q20: =VLOOKUP(O20, Coordinates!$A$2:$C$6, 3, FALSE) -> -80.1918 | R20: 27 | S20: 238 | T20: 24 | U20: 79.206125 | V20: Fail | W20: 3.7801206 | X20: Sea | Y20: Route A | Z20: 834.5845
A21: skincare | B21: SKU19 | C21: 79.356124 | D21: 98 | E21: 833 | F21: 1362.9272 | G21: Unknown | H21: 4 | I21: 23 | J21: 56 | K21: 6 | L21: Carrier C | M21: 10.46768 | N21: Supplier 5 | O21: New York | P21: =VLOOKUP(O21, Coordinates!$A$2:$C$6, 2, FALSE) -> 40.7128 | Q21: =VLOOKUP(O21, Coordinates!$A$2:$C$6, 3, FALSE) -> -74.006 | R21: 8 | S21: 298 | T21: 8 | U21: 47.083028 | V21: Pass | W21: 0.99147591 | X21: Sea | Y21: Route B | Z21: 361.43558
A22: cosmetics | B22: SKU20 | C22: 30.600458 | D22: 94 | E22: 655 | F22: 18038.97 | G22: Male | H22: 100 | I22: 29 | J22: 50 | K22: 4 | L22: Carrier A | M22: 8.0971359 | N22: Supplier 5 | O22: Los Angeles | P22: =VLOOKUP(O22, Coordinates!$A$2:$C$6, 2, FALSE) -> 34.0522 | Q22: =VLOOKUP(O22, Coordinates!$A$2:$C$6, 3, FALSE) -> -118.2437 | R22: 28 | S22: 820 | T22: 1 | U22: 91.844702 | V22: Pending | W22: 4.3735028 | X22: Sea | Y22: Route C | Z22: 337.14347
A23: cosmetics | B23: SKU21 | C23: 35.512889 | D23: 6 | E23: 296 | F23: 9460.6337 | G23: Female | H23: 3 | I23: 6 | J23: 73 | K23: 3 | L23: Carrier C | M23: 4.8852631 | N23: Supplier 3 | O23: Houston | P23: =VLOOKUP(O23, Coordinates!$A$2:$C$6, 2, FALSE) -> 29.7604 | Q23: =VLOOKUP(O23, Coordinates!$A$2:$C$6, 3, FALSE) -> -95.3698 | R23: 20 | S23: 884 | T23: 3 | U23: 89.458225 | V23: Pending | W23: 2.7943565 | X23: Air | Y23: Route B | Z23: 974.30959
A24: Haircare | B24: SKU22 | C24: 70.703715 | D24: 81 | E24: 568 | F24: 2376.4887 | G24: Unknown | H24: 1 | I24: 18 | J24: 51 | K24: 6 | L24: Carrier A | M24: 9.7513238 | N24: Supplier 2 | O24: Houston | P24: =VLOOKUP(O24, Coordinates!$A$2:$C$6, 2, FALSE) -> 29.7604 | Q24: =VLOOKUP(O24, Coordinates!$A$2:$C$6, 3, FALSE) -> -95.3698 | R24: 15 | S24: 460 | T24: 29 | U24: 50.203165 | V24: Fail | W24: 0.23005679 | X24: Rail | Y24: Route A | Z24: 954.83953
A25: skincare | B25: SKU23 | C25: 63.714909 | D25: 89 | E25: 803 | F25: 1620.9101 | G25: Non-binary | H25: 11 | I25: 25 | J25: 52 | K25: 10 | L25: Carrier A | M25: 14.465081 | N25: Supplier 1 | O25: Miami | P25: =VLOOKUP(O25, Coordinates!$A$2:$C$6, 2, FALSE) -> 25.7617 | Q25: =VLOOKUP(O25, Coordinates!$A$2:$C$6, 3, FALSE) -> -80.1918 | R25: 8 | S25: 749 | T25: 22 | U25: 93.489232 | V25: Pending | W25: 4.4541626 | X25: Road | Y25: Route A | Z25: 892.46455
A26: Skincare | B26: SKU24 | C26: 65.153014 | D26: 69 | E26: 929 | F26: 9962.2213 | G26: Male | H26: 2 | I26: 29 | J26: 18 | K26: 9 | L26: Carrier B | M26: 12.67529 | N26: Supplier 2 | O26: New York | P26: =VLOOKUP(O26, Coordinates!$A$2:$C$6, 2, FALSE) -> 40.7128 | Q26: =VLOOKUP(O26, Coordinates!$A$2:$C$6, 3, FALSE) -> -74.006 | R26: 14 | S26: 509 | T26: 6 | U26: 36.915679 | V26: Pass | W26: 1.7450299 | X26: Sea | Y26: Route B | Z26: 292.93219
A27: haircare | B27: SKU25 | C27: 26.744987 | D27: 69 | E27: 145 | F27: 3599.2897 | G27: Unknown | H27: 69 | I27: 11 | J27: 23 | K27: 2 | L27: Carrier B | M27: 2.5227552 | N27: Supplier 2 | O27: Houston | P27: =VLOOKUP(O27, Coordinates!$A$2:$C$6, 2, FALSE) -> 29.7604 | Q27: =VLOOKUP(O27, Coordinates!$A$2:$C$6, 3, FALSE) -> -95.3698 | R27: 13 | S27: 745 | T27: 1 | U27: 46.056363 | V27: Pass | W27: 1.7107828 | X27: Sea | Y27: Route A | Z27: 628.92009
... A37: Cosmetics | B37: SKU35 | C37: 36.865085 | D37: 66 | E37: 257 | F37: 8526.8942 | G37: Unknown | H37: 80 | I37: 20 | J37: 84 | K37: 2 | L37: Carrier B | M37: 7.6116955 | N37: Supplier 3 | O37: Miami | P37: =VLOOKUP(O37, Coordinates!$A$2:$C$6, 2, FALSE) -> 25.7617 | Q37: =VLOOKUP(O37, Coordinates!$A$2:$C$6, 3, FALSE) -> -80.1918 | R37: 7 | S37: 803 | T37: 8 | U37: 90.59747 | V37: Pass | W37: 0.27204414 | X37: Rail | Y37: Route C | Z37: 898.2572
A38: Haircare | B38: SKU36 | C38: 54.922939 | D38: 9 | E38: 782 | F38: 3850.1592 | H38: 67 | I38: 18 | J38: 16 | K38: 1 | L38: Carrier C | M38: 6.7097503 | N38: Supplier 2 | O38: Los Angeles | P38: =VLOOKUP(O38, Coordinates!$A$2:$C$6, 2, FALSE) -> 34.0522 | Q38: =VLOOKUP(O38, Coordinates!$A$2:$C$6, 3, FALSE) -> -118.2437 | R38: 17 | S38: 596 | T38: 29 | U38: 13.408391 | V38: Pass | W38: 4.4726145 | X38: Air | Y38: Route A | Z38: 579.97872
A39: skincare | B39: SKU37 | C39: 50.75531 | D39: 100 | E39: 704 | F39: 7095.7356 | G39: Male | H39: 21 | I39: 27 | J39: 75 | K39: 5 | L39: Carrier C | M39: 5.947062 | N39: Supplier 5 | O39: Chicago | P39: =VLOOKUP(O39, Coordinates!$A$2:$C$6, 2, FALSE) -> 41.8781 | Q39: =VLOOKUP(O39, Coordinates!$A$2:$C$6, 3, FALSE) -> -87.6298 | R39: 29 | S39: 155 | T39: 12 | U39: 82.646079 | V39: Pending | W39: 1.6360791 | X39: Sea | Y39: Route C | Z39: 586.86919
A40: skincare | B40: SKU38 | C40: 21.804279 | D40: 86 | E40: 390 | F40: 3606.2443 | G40: Non-binary | H40: 31 | I40: 21 | J40: 24 | K40: 2 | L40: Carrier A | M40: 6.9222373 | N40: Supplier 4 | O40: Miami | P40: =VLOOKUP(O40, Coordinates!$A$2:$C$6, 2, FALSE) -> 25.7617 | Q40: =VLOOKUP(O40, Coordinates!$A$2:$C$6, 3, FALSE) -> -80.1918 | R40: 29 | S40: 558 | T40: 19 | U40: 97.864904 | V40: Fail | W40: 4.5468509 | X40: Road | Y40: Route C | Z40: 316.174
A41: Cosmetics | B41: SKU39 | C41: 23.007088 | D41: 64 | E41: 234 | F41: 4845.2927 | G41: Non-binary | H41: 21 | I41: 1 | J41: 81 | K41: 8 | L41: Carrier B | M41: 10.43121 | N41: Supplier 1 | O41: New York | P41: =VLOOKUP(O41, Coordinates!$A$2:$C$6, 2, FALSE) -> 40.7128 | Q41: =VLOOKUP(O41, Coordinates!$A$2:$C$6, 3, FALSE) -> -74.006 | R41: 22 | S41: 388 | T41: 14 | U41: 84.012097 | V41: Fail | W41: 4.5802582 | X41: Road | Y41: Route B | Z41: 642.53547
A42: cosmetics | B42: SKU40 | C42: 36.400673 | D42: 86 | E42: 275 | F42: 9009.1667 | G42: Unknown | H42: 26 | I42: 29 | J42: 56 | K42: 8 | L42: Carrier B | M42: 7.0720748 | N42: Supplier 3 | O42: Los Angeles | P42: =VLOOKUP(O42, Coordinates!$A$2:$C$6, 2, FALSE) -> 34.0522 | Q42: =VLOOKUP(O42, Coordinates!$A$2:$C$6, 3, FALSE) -> -118.2437 | R42: 22 | S42: 642 | T42: 30 | U42: 87.33507 | V42: Fail | W42: 4.0526289 | X42: Rail | Y42: Route C | Z42: 443.03458
A43: cosmetics | B43: SKU41 | C43: 29.520006 | D43: 22 | E43: 775 | F43: 20590.204 | G43: Female | H43: 14 | I43: 24 | J43: 99 | K43: 1 | L43: Carrier B | M43: 5.5391344 | N43: Supplier 4 | O43: Miami | P43: =VLOOKUP(O43, Coordinates!$A$2:$C$6, 2, FALSE) -> 25.7617 | Q43: =VLOOKUP(O43, Coordinates!$A$2:$C$6, 3, FALSE) -> -80.1918 | R43: 25 | S43: 569 | T43: 19 | U43: 85.087344 | V43: Pending | W43: 4.299167 | X43: Sea | Y43: Route B | Z43: 682.10335
A44: Cosmetics | B44: SKU42 | C44: 34.920073 | D44: 34 | E44: 815 | F44: 25613.874 | G44: Unknown | H44: 43 | I44: 30 | J44: 49 | K44: 4 | L44: Carrier A | M44: 11.410927 | N44: Supplier 1 | O44: Chicago | P44: =VLOOKUP(O44, Coordinates!$A$2:$C$6, 2, FALSE) -> 41.8781 | Q44: =VLOOKUP(O44, Coordinates!$A$2:$C$6, 3, FALSE) -> -87.6298 | R44: 18 | S44: 488 | T44: 27 | U44: 85.926466 | V44: Pass | W44: 3.5180391 | X44: Air | Y44: Route A | Z44: 370.67172
A45: cosmetics | B45: SKU43 | C45: 24.808443 | D45: 55 | E45: 419 | F45: 9355.2638 | G45: Unknown | H45: 85 | I45: 8 | J45: 51 | K45: 9 | L45: Carrier A | M45: 3.8416 | N45: Supplier 1 | O45: Los Angeles | P45: =VLOOKUP(O45, Coordinates!$A$2:$C$6, 2, FALSE) -> 34.0522 | Q45: =VLOOKUP(O45, Coordinates!$A$2:$C$6, 3, FALSE) -> -118.2437 | R45: 6 | S45: 520 | T45: 17 | U45: 92.913997 | V45: Pass | W45: 4.6045256 | X45: Air | Y45: Route C | Z45: 744.15553
A46: HAIRCARE | B46: SKU44 | C46: 80.082085 | D46: 29 | E46: 202 | F46: 4395.2679 | G46: Non-binary | H46: 91 | I46: 3 | J46: 60 | K46: 5 | L46: Carrier A | M46: 3.8270721 | N46: Supplier 2 | O46: Houston | P46: =VLOOKUP(O46, Coordinates!$A$2:$C$6, 2, FALSE) -> 29.7604 | Q46: =VLOOKUP(O46, Coordinates!$A$2:$C$6, 3, FALSE) -> -95.3698 | R46: 30 | S46: 612 | T46: 28 | U46: 90.121988 | V46: Fail | W46: 4.0604659 | X46: Air | Y46: Route C | Z46: 657.01251
A47: skincare | B47: SKU45 | C47: 60.304082 | D47: 38 | E47: 327 | F47: 6976.6671 | G47: Male | H47: 8 | I47: 1 | J47: 44 | K47: 10 | L47: Carrier C | M47: 10.750098 | N47: Supplier 1 | O47: Chicago | P47: =VLOOKUP(O47, Coordinates!$A$2:$C$6, 2, FALSE) -> 41.8781 | Q47: =VLOOKUP(O47, Coordinates!$A$2:$C$6, 3, FALSE) -> -87.6298 | R47: 10 | S47: 809 | T47: 16 | U47: 80.724972 | V47: Pass | W47: 3.0492953 | X47: Sea | Y47: Route B | Z47: 527.03558
A48: Cosmetics | B48: SKU46 | C48: 29.72314 | D48: 97 | E48: 60 | F48: 1605.0496 | G48: Non-binary | H48: 33 | I48: 20 | J48: 50 | K48: 6 | L48: Carrier C | M48: 13.133891 | N48: Supplier 5 | O48: New York | P48: =VLOOKUP(O48, Coordinates!$A$2:$C$6, 2, FALSE) -> 40.7128 | Q48: =VLOOKUP(O48, Coordinates!$A$2:$C$6, 3, FALSE) -> -74.006 | R48: 18 | S48: 656 | T48: 19 | U48: 81.01717 | V48: Pass | W48: 3.2935135 | X48: Sea | Y48: Route B | Z48: 187.00519
A49: skincare | B49: SKU47 | C49: 23.021011 | D49: 18 | E49: 905 | F49: 2143.3022 | G49: Unknown | H49: 0 | I49: 30 | J49: 94 | K49: 3 | L49: Carrier A | M49: 4.3769518 | N49: Supplier 1 | O49: New York | P49: =VLOOKUP(O49, Coordinates!$A$2:$C$6, 2, FALSE) -> 40.7128 | Q49: =VLOOKUP(O49, Coordinates!$A$2:$C$6, 3, FALSE) -> -74.006 | R49: 24 | S49: 658 | T49: 5 | U49: 15.889825 | V49: Pass | W49: 0.73634212 | X49: Sea | Y49: Route A | Z49: 664.27135
...

Sheet Coordinates
A1: Location (Hub) | B1: Latitude | C1: Longitude
A2: Los Angeles | B2: 34.0522 | C2: -118.2437
A3: New York | B3: 40.7128 | C3: -74.006
A4: Chicago | B4: 41.8781 | C4: -87.6298
A5: Houston | B5: 29.7604 | C5: -95.3698
A6: Miami | B6: 25.7617 | C6: -80.1918
